Workbook

Sheet Raw
A1: Group | B1: Id | C1: Participation date | D1: First game | E1: Birth year | F1: study | G1: mother tongue | H1: General Info: Q1 | I1: General Info: Q2 | J1: General Info: Q3 | K1: General Info: Q4 | L1: General Info: Q5 | M1: General Info: Q6 | N1: General Info: Q7 | O1: Volleyball: Q1 | P1: Volleyball: Q2 | Q1: Volleyball: Q3 | R1: Volleyball: Q4 | S1: Volleyball: Q5 | T1: Volleyball: Q6 | U1: Volleyball: Q7 | V1: Team: Q1 | W1: Team: Q2 | X1: Team: Q3 | Y1: Team: Q4 | Z1: Team: Q5-1 | AA1: Team: Q5-2 | AB1: Team: Q5-3 | AC1: Team: Q5-4 | AD1: Team: Q5-5 | AE1: Team: Q5-6 | AF1: Team: Q5-7 | AG1: Team: Q5-8 | AH1: Team: Q5-9 | AI1: Team: Q6-1 | AJ1: Team: Q6-2 | AK1: Team: Q6-3 | AL1: Team: Q6-4 | AM1: Team: Q6-5 | AN1: Team: Q6-6 | AO1: Team: Q6-7 | AP1: Team: Q6-8 | AQ1: Team: Q6-9 | AR1: Team: Q7-12 | AS1: Team: Q7-13 | AT1: Team: Q7-14 | AU1: Team: Q7-15 | AV1: Team: Q7-16 | AW1: Team: Q7-17 | AX1: Team: Q7-18 | AY1: Team: Q7-19 | AZ1: Team: Q7-23 | BA1: Team: Q7-24 | BB1: Team: Q7-25 | BC1: Team: Q7-26 | BD1: Team: Q7-27 | BE1: Team: Q7-28 | BF1: Team: Q7-29 | BG1: Team: Q7-34 | BH1: Team: Q7-35 | BI1: Team: Q7-36 | BJ1: Team: Q7-37 | BK1: Team: Q7-38 | BL1: Team: Q7-39 | BM1: Team: Q7-45 | BN1: Team: Q7-46 | BO1: Team: Q7-47 | BP1: Team: Q7-48 | BQ1: Team: Q7-49 | BR1: Team: Q7-56 | BS1: Team: Q7-57 | BT1: Team: Q7-58 | BU1: Team: Q7-59 | BV1: Team: Q7-67 | BW1: Team: Q7-68 | BX1: Team: Q7-69 | BY1: Team: Q7-78 | BZ1: Team: Q7-79 | CA1: Team: Q7-89 | CB1: Team - Player (1) - A/B | CC1: Team - Player (2) - A/B | CD1: Volley - Player (1) - A/B | CE1: Volley - Player (2) - A/B | CF1: stranger - Player (1) - A/B | CG1: stranger - Player (2) - A/B | CH1: Team - Player (1) - In | CI1: Team - Player (1) - A/B | CJ1: Team - Player (2) - A/B | CK1: Volley - Player (1) - In | CL1: Volley - Player (1) - A/B | CM1: Volley - Player (2) - A/B | CN1: Stranger - Player (1) - In | CO1: Stranger - Player (1) - A/B | CP1: Stranger - Player (2) - A/B
A2: M1 | B2: 1 | C2: 40876 | D2: one shot | E2: 1991 | F2: Economics | G2: French | H2: No | I2: Fair | J2: Cooperate | K2: Distrust | L2: PS | M2: Other | N2: Rouen | O2: 8 | P2: 10 | Q2: * | R2: Handball | S2: VolleyballSt Orens | T2: OM | U2: Toulouse | V2: 2 | W2: 2 | X2: 8 | Y2: Best team | Z2: * | AA2: like a lot | AB2: like a lot | AC2: like a lot | AD2: like | AE2: like a lot | AF2: like | AG2: like | AH2: * | AI2: * | AJ2: like a lot | AK2: like a lot | AL2: like a lot | AM2: like | AN2: like a lot | AO2: like | AP2: like | AQ2: * | AR2: * | AS2: * | AT2: * | AU2: * | AV2: * | AW2: * | AX2: * | AY2: * | AZ2: 1 | BA2: 0 | BB2: 0 | BC2: 1 | BD2: 0 | BE2: 1 | BF2: * | BG2: 1 | BH2: 1 | BI2: 1 | BJ2: 1 | BK2: 1 | BL2: * | BM2: 1 | BN2: 0 | BO2: 0 | BP2: 0 | BQ2: * | BR2: 0 | BS2: 1 | BT2: 0 | BU2: * | BV2: 0 | BW2: 1 | BX2: * | BY2: 0 | BZ2: * | CA2: * | CB2: B | CC2: B | CD2: B | CE2: B | CF2: B | CG2: B | CH2: YES | CI2: B | CJ2: B | CK2: YES | CL2: A | CM2: B | CN2: YES | CO2: B | CP2: A
A3: M1 | B3: 2 | C3: 40876 | D3: one shot | E3: 1988 | F3: Law | G3: French | H3: No | I3: Unfair | J3: Cooperate | K3: Distrust | L3: PS | M3: Catholicism | N3: Toulouse | O3: 3 | P3: 8 | Q3: * | R3: soccer, tennis, mountain bike, bodyboard, swimming | S3: AS Cannes | T3: TFC, AC Milan | U3: Toulouse | V3: 1 | W3: 1 | X3: 5 | Y3: Friends | Z3: like a lot | AA3: * | AB3: like a lot | AC3: like | AD3: like a lot | AE3: like a lot | AF3: like | AG3: like | AH3: * | AI3: like | AJ3: * | AK3: like a lot | AL3: like | AM3: like | AN3: like a lot | AO3: indifferent | AP3: like | AQ3: * | AR3: * | AS3: 0 | AT3: 1 | AU3: 0 | AV3: 1 | AW3: 0 | AX3: 0 | AY3: * | AZ3: * | BA3: * | BB3: * | BC3: * | BD3: * | BE3: * | BF3: * | BG3: 1 | BH3: 0 | BI3: 0 | BJ3: 0 | BK3: 0 | BL3: * | BM3: 0 | BN3: 0 | BO3: 0 | BP3: 0 | BQ3: * | BR3: 0 | BS3: 1 | BT3: 0 | BU3: * | BV3: 0 | BW3: 0 | BX3: * | BY3: 0 | BZ3: * | CA3: * | CB3: B | CC3: B | CD3: A | CE3: B | CF3: A | CG3: B | CH3: YES | CI3: A | CJ3: B | CK3: YES | CL3: A | CM3: B | CN3: YES | CO3: A | CP3: B
A4: M1 | B4: 3 | C4: 40876 | D4: one shot | E4: 1987 | F4: Management | G4: French | H4: Yes | I4: Fair | J4: Cooperate | K4: Trust | L4: PCF | M4: Protestantism | N4: Niort | O4: 12 | P4: 10 | Q4: Gym | R4: Trail, Running, Cycling, tennis | S4: Tours, Poitier, Montpelier | T4: * | U4: Toulouse, Montpellier | V4: 3 | W4: 3 | X4: 5 | Y4: Best team | Z4: like a lot | AA4: like a lot | AB4: * | AC4: like a lot | AD4: like a lot | AE4: like a lot | AF4: like a lot | AG4: like a lot | AH4: * | AI4: like | AJ4: like a lot | AK4: * | AL4: like | AM4: like a lot | AN4: like | AO4: like | AP4: like | AQ4: * | AR4: 0 | AS4: * | AT4: 0 | AU4: 0 | AV4: 1 | AW4: 0 | AX4: 0 | AY4: * | AZ4: * | BA4: 0 | BB4: 0 | BC4: 0 | BD4: 0 | BE4: 0 | BF4: * | BG4: * | BH4: * | BI4: * | BJ4: * | BK4: * | BL4: * | BM4: 0 | BN4: 0 | BO4: 0 | BP4: 0 | BQ4: * | BR4: 0 | BS4: 0 | BT4: 0 | BU4: * | BV4: 0 | BW4: 0 | BX4: * | BY4: 0 | BZ4: * | CA4: * | CB4: A | CC4: B | CD4: B | CE4: B | CF4: B | CG4: B | CH4: NO | CI4: B | CJ4: B | CK4: NO | CL4: B | CM4: A | CN4: NO | CO4: B | CP4: A
A5: M1 | B5: 4 | C5: 40876 | D5: one shot | E5: 1986 | F5: Law | G5: Polish | H5: Yes | I5: Fair | J5: Defect | K5: Distrust | L5: UMP | M5: Catholicism | N5: Gracovie (Poland) | O5: 9 | P5: 2 | Q5: * | R5: Basketball | S5: Resovia Rzeszow (??) | T5: Barca | U5: Toulouse | V5: 2 | W5: 2 | X5: 3 | Y5: Friends | Z5: like | AA5: like | AB5: like a lot | AC5: * | AD5: like a lot | AE5: like | AF5: like | AG5: like | AH5: * | AI5: like | AJ5: like | AK5: like | AL5: * | AM5: like | AN5: like | AO5: like | AP5: like | AQ5: * | AR5: 1 | AS5: 1 | AT5: * | AU5: 0 | AV5: 1 | AW5: 0 | AX5: 0 | AY5: * | AZ5: 1 | BA5: * | BB5: 0 | BC5: 1 | BD5: 0 | BE5: 0 | BF5: * | BG5: * | BH5: 1 | BI5: 0 | BJ5: 1 | BK5: 0 | BL5: * | BM5: * | BN5: * | BO5: * | BP5: * | BQ5: * | BR5: 0 | BS5: 0 | BT5: 0 | BU5: * | BV5: 0 | BW5: 1 | BX5: * | BY5: 0 | BZ5: * | CA5: * | CB5: A | CC5: A | CD5: A | CE5: B | CF5: A | CG5: B | CH5: YES | CI5: A | CJ5: A | CK5: YES | CL5: B | CM5: A | CN5: YES | CO5: A | CP5: B
A6: M1 | B6: 5 | C6: 40876 | D6: one shot | E6: 1989 | F6: Politics | G6: French | H6: No | I6: Fair | J6: Cooperate | K6: Trust | L6: PS | M6: Other | N6: Paris | O6: 5 | P6: 2 | Q6: * | R6: Tennis, soccer, kayak | S6: Spacers | T6: Guingamp | U6: Toulouse | V6: 3 | W6: 3 | X6: 7 | Y6: Best team | Z6: like a lot | AA6: like a lot | AB6: like a lot | AC6: like a lot | AD6: * | AE6: like a lot | AF6: like a lot | AG6: like a lot | AH6: * | AI6: like a lot | AJ6: like a lot | AK6: like a lot | AL6: like a lot | AM6: * | AN6: like a lot | AO6: like a lot | AP6: like a lot | AQ6: * | AR6: 1 | AS6: 1 | AT6: 1 | AU6: * | AV6: 1 | AW6: 0 | AX6: 1 | AY6: * | AZ6: 1 | BA6: 1 | BB6: * | BC6: 1 | BD6: 0 | BE6: 1 | BF6: * | BG6: 1 | BH6: * | BI6: 0 | BJ6: 0 | BK6: 1 | BL6: * | BM6: * | BN6: 1 | BO6: 0 | BP6: 1 | BQ6: * | BR6: * | BS6: * | BT6: * | BU6: * | BV6: 0 | BW6: 1 | BX6: * | BY6: 0 | BZ6: * | CA6: * | CB6: B | CC6: B | CD6: B | CE6: B | CF6: B | CG6: B | CH6: YES | CI6: B | CJ6: B | CK6: YES | CL6: B | CM6: B | CN6: YES | CO6: B | CP6: B
A7: M1 | B7: 6 | C7: 40876 | D7: one shot | E7: 1984 | F7: Computer Sc | G7: French | H7: No | I7: Unfair | J7: Cooperate | K7: Distrust | L7: Other | M7: Other | N7: Nice | O7: 11 | P7: 10 | Q7: Beach volley | R7: Swimming, running | S7: Nice, Monaco | T7: * | U7: Naitonal team | V7: 0 | W7: 0 | X7: 8 | Y7: indifferent | Z7: like a lot | AA7: like a lot | AB7: like a lot | AC7: like a lot | AD7: like a lot | AE7: * | AF7: indifferent | AG7: like a lot | AH7: * | AI7: like a lot | AJ7: like a lot | AK7: like | AL7: like | AM7: like | AN7: * | AO7: indifferent | AP7: like | AQ7: * | AR7: 1 | AS7: 1 | AT7: 1 | AU7: 1 | AV7: * | AW7: 0 | AX7: 1 | AY7: * | AZ7: 1 | BA7: 1 | BB7: 1 | BC7: * | BD7: 0 | BE7: 1 | BF7: * | BG7: 1 | BH7: 1 | BI7: * | BJ7: 0 | BK7: 1 | BL7: * | BM7: 1 | BN7: * | BO7: 0 | BP7: 1 | BQ7: * | BR7: 1 | BS7: 0 | BT7: 1 | BU7: * | BV7: * | BW7: * | BX7: * | BY7: 0 | BZ7: * | CA7: * | CB7: B | CC7: B | CD7: A | CE7: B | CF7: A | CG7: B | CH7: NO | CI7: A | CJ7: B | CK7: YES | CL7: A | CM7: B | CN7: NO | CO7: A | CP7: B
A8: M1 | B8: 8 | C8: 40876 | D8: one shot | E8: 1989 | F8: Law | G8: French | H8: Yes | I8: Unfair | J8: Defect | K8: Distrust | L8: PS | M8: Other | N8: Albi | O8: 8 | P8: 8 | Q8: tennis | R8: Basketball | S8: Toulouse | T8: Manchester United | U8: Toulouse | V8: 1 | W8: 1 | X8: 5 | Y8: Best team | Z8: like | AA8: like | AB8: like | AC8: like | AD8: like | AE8: like | AF8: like | AG8: * | AH8: * | AI8: like | AJ8: like | AK8: like | AL8: like | AM8: like | AN8: like | AO8: like | AP8: * | AQ8: * | AR8: 0 | AS8: 1 | AT8: 0 | AU8: 1 | AV8: 1 | AW8: 0 | AX8: * | AY8: * | AZ8: 0 | BA8: 0 | BB8: 0 | BC8: 1 | BD8: 0 | BE8: * | BF8: * | BG8: 1 | BH8: 0 | BI8: 1 | BJ8: 0 | BK8: * | BL8: * | BM8: 0 | BN8: 0 | BO8: 0 | BP8: * | BQ8: * | BR8: 1 | BS8: 0 | BT8: * | BU8: * | BV8: 0 | BW8: * | BX8: * | BY8: * | BZ8: * | CA8: * | CB8: A | CC8: A | CD8: A | CE8: B | CF8: A | CG8: B | CH8: YES | CI8: A | CJ8: B | CK8: YES | CL8: A | CM8: B | CN8: NO | CO8: A | CP8: B
A9: M1 | B9: 9 | C9: 40876 | D9: one shot | E9: 1989 | F9: Management | G9: French | H9: No | I9: Fair | J9: Defect | K9: Trust | L9: MoDem | M9: Other | N9: Groulhet | O9: 6 | P9: 2 | Q9: * | R9: squash | S9: Toulouse (TOAC TUC) | T9: Lyon | U9: Toulouse | V9: 1 | W9: 1 | X9: 0 | Y9: Best team | Z9: like | AA9: like | AB9: like | AC9: indifferent | AD9: like | AE9: like | AF9: indifferent | AG9: like | AH9: * | AI9: like | AJ9: like | AK9: like | AL9: indifferent | AM9: like | AN9: like | AO9: indifferent | AP9: like | AQ9: * | AR9: 1 | AS9: 1 | AT9: 0 | AU9: 1 | AV9: 1 | AW9: 0 | AX9: 0 | AY9: * | AZ9: 1 | BA9: 0 | BB9: 1 | BC9: 1 | BD9: 0 | BE9: 0 | BF9: * | BG9: 0 | BH9: 1 | BI9: 1 | BJ9: 0 | BK9: 0 | BL9: * | BM9: 0 | BN9: 0 | BO9: 0 | BP9: 0 | BQ9: * | BR9: 1 | BS9: 0 | BT9: 0 | BU9: * | BV9: 0 | BW9: 0 | BX9: * | BY9: 0 | BZ9: * | CA9: * | CB9: B | CC9: B | CD9: B | CE9: B | CF9: B | CG9: B | CH9: YES | CI9: A | CJ9: B | CK9: YES | CL9: A | CM9: B | CN9: NO | CO9: B | CP9: B
A10: M2 | B10: 1 | C10: 40876 | D10: one shot | E10: 1989 | F10: Economics | G10: French | H10: No | I10: Fair | J10: Don't know | K10: Distrust | L10: PS | M10: Catholicism | N10: Toulouse | O10: 8 | P10: 1 | Q10: * | R10: Roller | S10: Spacers | T10: Benfica | U10: Toulouse | V10: 5 | W10: 1 | X10: 3 | Y10: Friends | Z10: * | AA10: like a lot | AB10: like a lot | AC10: like a lot | AD10: like a lot | AE10: like | AF10: like | AG10: * | AH10: * | AI10: * | AJ10: like a lot | AK10: like a lot | AL10: like a lot | AM10: like | AN10: like | AO10: like | AP10: * | AQ10: * | AR10: * | AS10: * | AT10: * | AU10: * | AV10: * | AW10: * | AX10: * | AY10: * | AZ10: 1 | BA10: 1 | BB10: 0 | BC10: 1 | BD10: 0 | BE10: * | BF10: * | BG10: 1 | BH10: 1 | BI10: 1 | BJ10: 1 | BK10: * | BL10: * | BM10: 0 | BN10: 1 | BO10: 1 | BP10: * | BQ10: * | BR10: 1 | BS10: 0 | BT10: * | BU10: * | BV10: 0 | BW10: * | BX10: * | BY10: * | BZ10: * | CA10: * | CB10: A | CC10: B | CD10: A | CE10: B | CF10: A | CG10: B | CH10: YES | CI10: A | CJ10: B | CK10: NO | CL10: A | CM10: B | CN10: NO | CO10: A | CP10: B
A11: M2 | B11: 3 | C11: 40876 | D11: one shot | E11: 1982 | F11: Computer Sc | G11: French | H11: Yes | I11: Unfair | J11: Defect | K11: Distrust | L11: Other | M11: Catholicism | N11: Castres | O11: 4 | P11: 0 | Q11: * | R11: climbing | S11: Spacers | T11: TFC | U11: Castres, Toulouse | V11: 4 | W11: 3 | X11: 4 | Y11: Friends | Z11: like a lot | AA11: like a lot | AB11: * | AC11: like a lot | AD11: like a lot | AE11: like a lot | AF11: like a lot | AG11: + like a lot | AH11: * | AI11: like a lot | AJ11: like a lot | AK11: * | AL11: like a lot | AM11: like a lot | AN11: like a lot | AO11: like a lot | AP11: + like a lot | AQ11: * | AR11: 1 | AS11: * | AT11: 1 | AU11: 1 | AV11: 1 | AW11: 1 | AX11: * | AY11: * | AZ11: * | BA11: 1 | BB11: 1 | BC11: 1 | BD11: 1 | BE11: * | BF11: * | BG11: * | BH11: * | BI11: * | BJ11: * | BK11: * | BL11: * | BM11: 1 | BN11: 1 | BO11: 1 | BP11: * | BQ11: * | BR11: 1 | BS11: 1 | BT11: * | BU11: * | BV11: 1 | BW11: * | BX11: * | BY11: * | BZ11: * | CA11: * | CB11: B | CC11: B | CD11: B | CE11: B | CF11: B | CG11: B | CH11: NO | CI11: B | CJ11: B | CK11: NO | CL11: B | CM11: B | CN11: NO | CO11: B | CP11: B
A12: M2 | B12: 4 | C12: 40876 | D12: one shot | E12: 1985 | F12: Law | G12: French | H12: No | I12: don't know | J12: Defect | K12: don't know | L12: EELV | M12: Islam | N12: Lavelanet | O12: 5 | P12: 2 | Q12: rugby, tennis | R12: rugby, tennis | S12: Cuba (?) | T12: OM | U12: Toulouse | V12: 5 | W12: 1 | X12: 7 | Y12: Friends | Z12: like a lot | AA12: like a lot | AB12: like a lot | AC12: * | AD12: like | AE12: like | AF12: like a lot | AG12: * | AH12: * | AI12: like a lot | AJ12: like a lot | AK12: like a lot | AL12: * | AM12: like | AN12: like | AO12: like a lot | AP12: * | AQ12: * | AR12: 0 | AS12: 1 | AT12: 1 | AU12: 0 | AV12: 0 | AW12: 0 | AX12: * | AY12: * | AZ12: 1 | BA12: * | BB12: 0 | BC12: 0 | BD12: 0 | BE12: * | BF12: * | BG12: * | BH12: 0 | BI12: 0 | BJ12: 1 | BK12: * | BL12: * | BM12: * | BN12: * | BO12: * | BP12: * | BQ12: * | BR12: 0 | BS12: 0 | BT12: * | BU12: * | BV12: 0 | BW12: * | BX12: * | BY12: * | BZ12: * | CA12: * | CB12: B | CC12: B | CD12: B | CE12: A | CF12: A | CG12: B | CH12: YES | CI12: B | CJ12: B | CK12: YES | CL12: B | CM12: B | CN12: YES | CO12: A | CP12: B
A13: M2 | B13: 5 | C13: 40876 | D13: one shot | E13: 1989 | F13: Law | G13: Polish | H13: No | I13: don't know | J13: Cooperate | K13: Distrust | L13: UMP | M13: Catholicism | N13: Cracovie (Poland) | O13: 6 | P13: 2 | Q13: * | R13: ski, tennis | S13: nationa team | T13: Wisla Krakow | U13: * | V13: 0 | W13: 0 | X13: 0 | Y13: Best team | Z13: like | AA13: like | AB13: like | AC13: like | AD13: * | AE13: like | AF13: like | AG13: * | AH13: * | AI13: like | AJ13: like | AK13: like | AL13: like | AM13: * | AN13: like | AO13: like | AP13: * | AQ13: * | AR13: 0 | AS13: 1 | AT13: 1 | AU13: * | AV13: 0 | AW13: 0 | AX13: * | AY13: * | AZ13: 0 | BB13: * | BC13: 0 | BD13: 0 | BE13: * | BF13: * | BG13: 1 | BH13: * | BI13: 0 | BJ13: 0 | BK13: * | BL13: * | BM13: * | BN13: 0 | BO13: 0 | BP13: * | BQ13: * | BR13: * | BS13: * | BT13: * | BU13: * | BV13: 0 | BW13: * | BX13: * | BY13: * | BZ13: * | CA13: * | CB13: A | CC13: A | CD13: A | CE13: A | CF13: A | CG13: A | CH13: * | CI13: * | CJ13: * | CK13: * | CL13: * | CM13: * | CN13: * | CO13: * | CP13: *
A14: M2 | B14: 6 | C14: 40883 | D14: one shot | E14: 1987 | F14: Law | G14: Russian | H14: No | I14: don't know | J14: Defect | K14: Trust | L14: Other | M14: Other | N14: Arkhangdsk (Russia) | O14: 10 | P14: 5 | Q14: * | R14: soccer | S14: nationa team | T14: Zenit | U14: Perpignan | V14: 1 | W14: 1 | X14: 3 | Y14: indifferent | Z14: like | AA14: like | AB14: like | AC14: like | AD14: like | AE14: * | AF14: like | AG14: * | AH14: * | AI14: like | AJ14: like | AK14: like | AL14: like | AM14: like | AN14: * | AO14: like | AP14: * | AQ14: * | AR14: 0 | AS14: 1 | AT14: 0 | AU14: 0 | AV14: * | AW14: 0 | AX14: * | AY14: * | AZ14: 1 | BA14: 1 | BB14: 0 | BC14: * | BD14: 1 | BE14: * | BF14: * | BG14: 1 | BH14: 0 | BI14: * | BJ14: 1 | BK14: * | BL14: * | BM14: 0 | BN14: * | BO14: 1 | BP14: * | BQ14: * | BR14: * | BS14: 0 | BT14: * | BU14: * | BV14: * | BW14: * | BX14: * | BY14: * | BZ14: * | CA14: * | CB14: A | CC14: A | CD14: A | CE14: A | CF14: A | CG14: A | CH14: YES | CI14: A | CJ14: A | CK14: YES | CL14: A | CM14: A | CN14: YES | CO14: A | CP14: A
A15: M2 | B15: 7 | C15: 40876 | D15: one shot | E15: 1986 | F15: Law | G15: French | H15: Yes | I15: don't know | J15: Defect | K15: Distrust | L15: PS | M15: Protestantism | N15: Fort de France | O15: 7 | P15: 3 | Q15: * | R15: tennis, swimming | S15: Spacers | T15: Barca | U15: * | V15: 4 | W15: 3 | X15: 1 | Y15: indifferent | Z15: like | AA15: like | AB15: like | AC15: like | AD15: like | AE15: like | AF15: * | AG15: * | AH15: * | AI15: like | AJ15: like | AK15: like | AL15: like | AM15: indifferent | AN15: like | AO15: * | AP15: * | AQ15: * | AR15: 1 | AS15: 1 | AT15: 1 | AU15: 1 | AV15: 1 | AW15: * | AX15: * | AY15: * | AZ15: 1 | BA15: 1 | BB15: 1 | BC15: 1 | BD15: * | BE15: * | BF15: * | BG15: 1 | BH15: 1 | BI15: 1 | BJ15: * | BK15: * | BL15: * | BM15: 1 | BN15: 1 | BO15: * | BP15: * | BQ15: * | BR15: 1 | BS15: * | BT15: * | BU15: * | BV15: * | BW15: * | BX15: * | BY15: * | BZ15: * | CA15: * | CB15: B | CC15: B | CD15: A | CE15: B | CF15: A | CG15: B | CH15: NO | CI15: B | CJ15: B | CK15: NO | CL15: B | CM15: B | CN15: NO | CO15: B | CP15: B
A16: M2 | B16: 8 | C16: 40876 | D16: one shot | E16: 1986 | F16: AES | G16: French | H16: No | I16: don't know | J16: Cooperate | K16: Distrust | L16: PS | M16: Other | N16: Tizi-Ouzan (Algeria) | O16: 5 | P16: 4 | Q16: Boxing, Self-defense | R16: mountain-biking | S16: Spacers | T16: Real Madrid | U16: Toulouse | V16: 4 | W16: 4 | X16: 10 | Y16: Friends | Z16: like a lot | AA16: like a lot | AB16: like a lot | AC16: like a lot | AD16: like | AE16: like | AF16: like a lot | AG16: * | AH16: * | AI16: like a lot | AJ16: like a lot | AK16: like a lot | AL16: like a lot | AM16: like | AN16: like | AO16: like a lot | AP16: * | AQ16: * | AR16: 0 | AS16: 1 | AT16: 1 | AU16: 1 | AV16: 0 | AW16: 1 | AX16: * | AY16: * | AZ16: 1 | BA16: 1 | BB16: 0 | BC16: 1 | BD16: 1 | BE16: * | BF16: * | BG16: 1 | BH16: 1 | BI16: 1 | BJ16: 1 | BK16: * | BL16: * | BM16: 1 | BN16: 1 | BO16: 1 | BP16: * | BQ16: * | BR16: 1 | BS16: 1 | BT16: * | BU16: * | BV16: 0 | BW16: * | BX16: * | BY16: * | BZ16: * | CA16: * | CB16: B | CC16: A | CD16: B | CE16: A | CF16: B | CG16: A | CH16: NO | CI16: B | CJ16: A | CK16: NO | CL16: B | CM16: A | CN16: NO | CO16: B | CP16: A
A17: M3 | B17: 1 | C17: 40876 | D17: two stage | E17: 1988 | F17: Politics | G17: French | H17: No | I17: don't know | J17: Defect | K17: Distrust | L17: PS | M17: Catholicism | N17: Ris-Orangis | O17: 2 | P17: 2 | Q17: * | R17: ping pong | S17: Spacers, Nationa team | T17: Saint Etiennes, Napoli, National team | U17: Toulouse, national team | V17: 2 | W17: 1 | X17: 9 | Y17: Best team | Z17: * | AA17: like a lot | AB17: like a lot | AC17: like | AD17: like | AE17: like | AF17: like | AG17: like | AH17: * | AI17: * | AJ17: like a lot | AK17: like | AL17: like | AM17: like | AN17: like | AO17: like | AP17: like | AQ17: * | AR17: * | AS17: * | AT17: * | AU17: * | AV17: * | AW17: * | AX17: * | AY17: * | AZ17: 1 | BA17: 0 | BB17: 0 | BC17: 1 | BD17: 1 | BE17: 0 | BF17: * | BG17: 1 | BH17: 0 | BI17: 0 | BJ17: 1 | BK17: 0 | BL17: * | BM17: 0 | BN17: 0 | BO17: 0 | BP17: 0 | BQ17: * | BR17: 0 | BS17: 1 | BT17: 0 | BU17: * | BV17: 0 | BW17: 0 | BX17: * | BY17: 0 | BZ17: * | CA17: * | CB17: A | CC17: B | CD17: B | CE17: B | CF17: B | CG17: B | CH17: NO | CI17: B | CJ17: B | CK17: NO | CL17: B | CM17: B | CN17: YES | CO17: A | CP17: A
A18: M3 | B18: 2 | C18: 40876 | D18: two stage | E18: 1989 | F18: Politics | G18: French | H18: Yes | I18: Fair | J18: Defect | K18: Distrust | L18: EELV | M18: Judaisme | N18: Castres | O18: 10 | P18: 3 | Q18: * | R18: E-sport | S18: Spacers | T18: Nice | U18: Castres | V18: 4 | W18: 3 | X18: 6 | Y18: Friends | Z18: like a lot | AA18: * | AB18: like | AC18: like | AD18: like | AE18: like | AF18: like | AG18: indifferent | AH18: * | AI18: like a lot | AJ18: * | AK18: like | AL18: indifferent | AM18: like | AN18: like | AO18: like | AP18: indifferent | AQ18: * | AR18: * | AS18: 1 | AT18: 1 | AU18: 1 | AV18: 1 | AW18: 1 | AX18: 0 | AY18: * | AZ18: * | BA18: * | BB18: * | BC18: * | BD18: * | BE18: * | BF18: * | BG18: 1 | BH18: 1 | BI18: 1 | BJ18: 1 | BK18: 0 | BL18: * | BM18: 0 | BN18: 1 | BO18: 0 | BP18: 0 | BQ18: * | BR18: 1 | BS18: 1 | BT18: 0 | BU18: * | BV18: 1 | BW18: 0 | BX18: * | BY18: 0 | BZ18: * | CA18: * | CB18: A | CC18: B | CD18: A | CE18: B | CF18: A | CG18: B | CH18: YES | CI18: B | CJ18: B | CK18: YES | CL18: A | CM18: A | CN18: NO | CO18: B | CP18: A
A19: M3 | B19: 3 | C19: 40876 | D19: two stage | E19: 1990 | F19: Politics | G19: French | H19: No | I19: Fair | J19: Defect | K19: Distrust | L19: PS | M19: Catholicism | N19: Lyon | O19: 5 | P19: 3 | Q19: futsal | R19: soccer, ping-pong, cycling, ski | S19: spacers | T19: Lyon | U19: Agen | V19: 3 | W19: 3 | X19: 3 | Y19: Friends | Z19: like | AA19: like | AB19: * | AC19: like a lot | AD19: like | AE19: like a lot | AF19: like a lot | AG19: like | AH19: * | AI19: like | AJ19: like | AK19: * | AL19: like a lot | AM19: like | AN19: like a lot | AO19: like | AP19: like | AQ19: * | AR19: 1 | AS19: * | AT19: 0 | AU19: 0 | AV19: 1 | AW19: 0 | AX19: 0 | AY19: * | AZ19: * | BA19: 0 | BB19: 0 | BC19: 1 | BD19: 0 | BE19: 0 | BF19: * | BG19: * | BH19: * | BI19: * | BJ19: * | BK19: * | BL19: * | BM19: 0 | BN19: 0 | BO19: 0 | BP19: 0 | BQ19: * | BR19: 0 | BS19: 1 | BT19: 0 | BU19: * | BV19: 1 | BW19: 0 | BX19: * | BY19: 1 | BZ19: * | CA19: * | CB19: B | CC19: B | CD19: A | CE19: B | CF19: A | CG19: B | CH19: YES | CI19: A | CJ19: A | CK19: YES | CL19: B | CM19: B | CN19: NO | CO19: A | CP19: B
A20: M3 | B20: 4 | C20: 40876 | D20: two stage | E20: 1990 | F20: Politics | G20: French | H20: No | I20: Unfair | J20: Defect | K20: Trust | L20: UMP | M20: Catholicism | N20: Paris | O20: 1 | P20: 2 | Q20: * | R20: Salsa, swimming | S20: Spacers | T20: Lyon | U20: Clermont | V20: 1 | W20: 1 | X20: 3 | Y20: indifferent | Z20: like a lot | AA20: like | AB20: like a lot | AC20: * | AD20: like | AE20: like | AF20: like | AG20: indifferent | AH20: * | AI20: like | AJ20: like | AK20: like a lot | AL20: * | AM20: like | AN20: like | AO20: indifferent | AP20: indifferent | AQ20: * | AR20: 1 | AS20: 0 | AT20: * | AU20: 0 | AV20: 0 | AW20: 0 | AX20: 0 | AY20: * | AZ20: 1 | BA20: * | BB20: 0 | BC20: 0 | BD20: 0 | BE20: 0 | BF20: * | BG20: * | BH20: 0 | BI20: 1 | BJ20: 0 | BK20: 0 | BL20: * | BM20: * | BN20: * | BO20: * | BP20: * | BQ20: * | BR20: 0 | BS20: 0 | BT20: 0 | BU20: * | BV20: 0 | BW20: 0 | BX20: * | BY20: 0 | BZ20: * | CA20: * | CB20: B | CC20: A | CD20: B | CE20: B | CF20: A | CG20: B | CH20: YES | CI20: A | CJ20: A | CK20: YES | CL20: B | CM20: A | CN20: YES | CO20: B | CP20: B
A21: M3 | B21: 5 | C21: 40876 | D21: two stage | E21: 1993 | F21: Politics | G21: French | H21: No | I21: don't know | J21: Don't know | K21: don't know | L21: PS | M21: Other | N21: Eloise | O21: 4 | P21: 3 | Q21: rugby | R21: rugby, mountain bike, running | S21: spacers | T21: Evian Thonon Gaillard | U21: Toulouse | V21: 2 | W21: 1 | X21: 7 | Y21: Friends | Z21: like a lot | AA21: like | AB21: like a lot | AC21: like | AD21: * | AE21: like a lot | AF21: like a lot | AG21: like | AH21: * | AI21: like | AJ21: like | AK21: like | AL21: like | AM21: * | AN21: like a lot | AO21: like a lot | AP21: like | AQ21: * | AR21: 1 | AS21: 1 | AT21: 1 | AU21: * | AV21: 1 | AW21: 1 | AX21: 0 | AY21: * | AZ21: 1 | BA21: 1 | BB21: * | BC21: 1 | BD21: 1 | BE21: 0 | BF21: * | BG21: 0 | BH21: * | BI21: 0 | BJ21: 0 | BK21: 0 | BL21: * | BM21: * | BN21: 1 | BO21: 0 | BP21: 0 | BQ21: * | BR21: * | BS21: * | BT21: * | BU21: * | BV21: 1 | BW21: 0 | BX21: * | BY21: 0 | BZ21: * | CA21: * | CB21: B | CC21: B | CD21: B | CE21: B | CF21: B | CG21: B | CH21: YES | CI21: B | CJ21: B | CK21: NO | CL21: A | CM21: B | CN21: NO | CO21: B | CP21: B
A22: M3 | B22: 6 | C22: 40876 | D22: two stage | E22: 1990 | F22: Politics | G22: French | H22: No | I22: Fair | J22: Defect | K22: Trust | L22: other | M22: other | N22: Charliar | O22: 8 | P22: 6 | Q22: * | R22: soccer, badminton | S22: spacers | T22: Lyon | U22: * | V22: 4 | W22: 4 | X22: 8 | Y22: Best team | Z22: like a lot | AA22: like a lot | AB22: like a lot | AC22: like a lot | AD22: like a lot | AE22: * | AF22: like a lot | AG22: like a lot | AH22: * | AI22: like a lot | AJ22: like | AK22: like a lot | AL22: like | AM22: like | AN22: * | AO22: like a lot | AP22: like | AQ22: * | AR22: 1 | AS22: 1 | AT22: 0 | AU22: 1 | AV22: * | AW22: 1 | AX22: 1 | AY22: * | AZ22: 0 | BA22: 0 | BB22: 1 | BC22: * | BD22: 0 | BE22: 0 | BF22: * | BG22: 1 | BH22: 0 | BI22: * | BJ22: 0 | BK22: 0 | BL22: * | BM22: 0 | BN22: * | BO22: 1 | BP22: 0 | BQ22: * | BR22: * | BS22: 0 | BT22: 0 | BU22: * | BV22: * | BW22: * | BX22: * | BY22: 0 | BZ22: * | CA22: * | CB22: B | CC22: B | CD22: A | CE22: B | CF22: A | CG22: B | CH22: YES | CI22: B | CJ22: B | CK22: NO | CL22: B | CM22: B | CN22: NO | CO22: A | CP22: B
A23: M3 | B23: 7 | C23: 40876 | D23: two stage | E23: 1988 | F23: Politics | G23: French | H23: No | I23: Fair | J23: Cooperate | K23: don't know | L23: PS | M23: Other | N23: Clermont-Ferrand | O23: 3 | P23: 2 | Q23: Triathlon | R23: tennis | S23: * | T23: OM | U23: Clermont | V23: 3 | W23: 3 | X23: 7 | Y23: Best team | Z23: like a lot | AA23: like | AB23: like a lot | AC23: like | AD23: like a lot | AE23: like a lot | AF23: * | AG23: like | AH23: * | AI23: like a lot | AJ23: like | AK23: like a lot | AL23: like | AM23: like a lot | AN23: like a lot | AO23: * | AP23: like | AQ23: * | AR23: 1 | AS23: 1 | AT23: 0 | AU23: 1 | AV23: 1 | AW23: * | AX23: 1 | AY23: * | AZ23: 1 | BA23: 1 | BB23: 1 | BC23: 1 | BD23: * | BE23: 1 | BF23: * | BG23: 1 | BH23: 1 | BI23: 1 | BJ23: * | BK23: 1 | BL23: * | BM23: 1 | BN23: 1 | BO23: * | BP23: 0 | BQ23: * | BR23: 1 | BS23: * | BT23: 0 | BU23: * | BV23: * | BW23: 0 | BX23: * | BY23: * | BZ23: * | CA23: * | CB23: B | CC23: A | CD23: B | CE23: A | CF23: B | CG23: A | CH23: YES | CI23: B | CJ23: B | CK23: NO | CL23: B | CM23: A | CN23: NO | CO23: B | CP23: A
A24: M4 | B24: 1 | C24: 40876 | D24: two stage | E24: 1990 | F24: Economics | G24: French | H24: No | I24: Fair | J24: Don't know | K24: Trust | L24: PS | M24: Other | N24: Caen | O24: 1 | P24: 0 | Q24: Athletisme | R24: Soccer | S24: * | T24: Caen, OM, Real Madrid | U24: Toulouse | V24: 1 | W24: 0 | X24: 0 | Y24: Friends | Z24: * | AA24: like | AB24: indifferent | AC24: dislike | AD24: like | AE24: like | AF24: like | AG24: like a lot | AH24: * | AI24: * | AJ24: like | AK24: indifferent | AL24: indifferent | AM24: like | AN24: like | AO24: indifferent | AP24: like | AQ24: * | AR24: * | AS24: * | AT24: * | AU24: * | AV24: * | AW24: * | AX24: * | AY24: * | AZ24: 1 | BA24: 0 | BB24: 0 | BC24: 1 | BD24: 0 | BE24: 1 | BF24: * | BG24: 0 | BH24: 0 | BI24: 0 | BJ24: 0 | BK24: 1 | BL24: * | BM24: 0 | BN24: 1 | BO24: 0 | BP24: 1 | BQ24: * | BR24: 1 | BS24: 1 | BT24: 1 | BU24: * | BV24: 1 | BW24: 1 | BX24: * | BY24: 1 | BZ24: * | CA24: * | CB24: B | CC24: B | CD24: B | CE24: B | CF24: B | CG24: A | CH24: YES | CI24: B | CJ24: B | CK24: NO | CL24: B | CM24: B | CN24: NO | CO24: B | CP24: A
A25: M4 | B25: 2 | C25: 40876 | D25: two stage | E25: 1987 | F25: Computer Sc | G25: French | H25: Yes | I25: Unfair | J25: Defect | K25: Distrust | L25: PS | M25: Other | N25: Liury-organ | O25: 7 | P25: 0 | Q25: * | R25: soccer, running, rugby,ski | S25: Toulouse | T25: Toulouse | U25: Toulouse | V25: 1 | W25: 1 | X25: 0 | Y25: indifferent | Z25: like | AA25: * | AB25: like | AC25: like | AD25: like | AE25: like | AF25: like | AG25: like | AH25: * | AI25: like | AJ25: * | AK25: indifferent | AL25: like | AM25: like | AN25: like | AO25: like | AP25: like | AQ25: * | AR25: * | AS25: 1 | AT25: 1 | AU25: 1 | AV25: 1 | AW25: 0 | AX25: 1 | AY25: * | AZ25: * | BA25: * | BB25: * | BC25: * | BD25: * | BE25: * | BF25: * | BG25: 0 | BH25: 1 | BI25: 1 | BJ25: 0 | BK25: 1 | BL25: * | BM25: 1 | BN25: 1 | BO25: 1 | BP25: 1 | BQ25: * | BR25: 1 | BS25: 0 | BT25: 1 | BU25: * | BV25: 1 | BW25: 1 | BX25: * | BY25: 1 | BZ25: * | CA25: * | CB25: B | CC25: B | CD25: B | CE25: B | CF25: B | CG25: B | CH25: NO | CI25: B | CJ25: B | CK25: NO | CL25: B | CM25: B | CN25: NO | CO25: B | CP25: B
A26: M4 | B26: 3 | C26: 40883 | D26: two stage | E26: 1987 | F26: Law | G26: French | H26: No | I26: don't know | J26: Defect | K26: Distrust | L26: PS | M26: Other | N26: Paris | O26: 3 | P26: 0 | Q26: swimming | R26: rugby | S26: Nice | T26: * | U26: RCT | V26: 1 | W26: 0 | X26: 0 | Y26: Friends | Z26: indifferent | AA26: like | AB26: * | AC26: like | AD26: like | AE26: like | AF26: like | AG26: like | AH26: * | AI26: like | AJ26: like | AK26: * | AL26: like | AM26: like | AN26: like | AO26: like | AP26: like | AQ26: * | AR26: 0 | AS26: * | AT26: 0 | AU26: 0 | AV26: 0 | AW26: 0 | AX26: 0 | AY26: * | AZ26: * | BA26: 0 | BB26: 0 | BC26: 0 | BD26: 0 | BE26: 0 | BF26: * | BG26: * | BH26: * | BI26: * | BJ26: * | BK26: * | BL26: * | BM26: 0 | BN26: 1 | BO26: 0 | BP26: 0 | BQ26: * | BR26: 0 | BS26: 0 | BT26: 0 | BU26: * | BV26: 0 | BW26: 0 | BX26: * | BY26: 0 | BZ26: * | CA26: * | CB26: A | CC26: B | CD26: A | CE26: B | CF26: A | CG26: B | CH26: NO | CI26: A | CJ26: B | CK26: NO | CL26: A | CM26: B | CN26: NO | CO26: A | CP26: B
A27: M4 | B27: 4 | C27: 40876 | D27: two stage | E27: 1991 | F27: Law | G27: French | H27: No | I27: Fair | J27: Defect | K27: Trust | L27: PS | M27: Catholicism | N27: St Vallier | O27: 1 | P27: 1 | Q27: * | R27: ski,tennis,rugby | S27: Toulouse | T27: Lyon | U27: Clermont | V27: 0 | W27: 0 | X27: 6 | Y27: Friends | Z27: like a lot | AA27: like a lot | AB27: like a lot | AC27: * | AD27: like a lot | AE27: like a lot | AF27: like a lot | AG27: like a lot | AH27: * | AI27: indifferent | AJ27: indifferent | AK27: indifferent | AL27: * | AM27: like | AN27: like | AO27: like | AP27: like | AQ27: * | AR27: 1 | AS27: 0 | AT27: * | AU27: 0 | AV27: 0 | AW27: 1 | AX27: 0 | AY27: * | AZ27: 0 | BA27: * | BB27: 1 | BC27: 0 | BD27: 0 | BE27: 0 | BF27: * | BG27: * | BH27: 0 | BI27: 1 | BJ27: 0 | BK27: 1 | BL27: * | BM27: * | BN27: * | BO27: * | BP27: * | BQ27: * | BR27: 0 | BS27: 1 | BT27: 0 | BU27: * | BV27: 1 | BW27: 1 | BX27: * | BY27: 0 | BZ27: * | CA27: * | CB27: B | CC27: B | CD27: B | CE27: B | CF27: B | CG27: B | CH27: YES | CI27: B | CJ27: B | CK27: YES | CL27: B | CM27: B | CN27: YES | CO27: B | CP27: B
A28: M4 | B28: 5 | C28: 40876 | D28: two stage | E28: 1993 | F28: Law | G28: Italian | H28: No | I28: Fair | J28: Don't know | K28: Distrust | L28: PS | M28: Other | N28: Venise (Italy) | O28: 1 | P28: 3 | Q28: swimming | R28: soccer | S28: spacers | T28: AC Milan | U28: Benetton Treviso | V28: 1 | W28: 1 | X28: 6 | Y28: Friends | Z28: like | AA28: like | AB28: like | AC28: like | AD28: * | AE28: like | AF28: like | AG28: like | AH28: * | AI28: like | AJ28: like | AK28: like | AL28: like | AM28: * | AN28: like | AO28: like | AP28: like | AQ28: * | AR28: 1 | AS28: 0 | AT28: 0 | AU28: * | AV28: 1 | AW28: 0 | AX28: 0 | AY28: * | AZ28: 0 | BA28: 0 | BB28: * | BC28: 0 | BD28: 0 | BE28: 0 | BF28: * | BG28: 0 | BH28: * | BI28: 0 | BJ28: 0 | BK28: 0 | BL28: * | BM28: * | BN28: 0 | BO28: 1 | BP28: 0 | BQ28: * | BR28: * | BS28: * | BT28: * | BU28: * | BV28: 1 | BW28: 1 | BX28: * | BY28: 0 | BZ28: * | CA28: * | CB28: A | CC28: B | CD28: A | CE28: B | CF28: A | CG28: B | CH28: NO | CI28: A | CJ28: A | CK28: NO | CL28: A | CM28: A | CN28: NO | CO28: A | CP28: B
A29: M4 | B29: 6 | C29: 40876 | D29: two stage | E29: 1991 | F29: Management | G29: French | H29: No | I29: Fair | J29: Defect | K29: Distrust | L29: UMP | M29: Bouddhism | N29: Paris | O29: 5 | P29: 1 | Q29: ping pong | R29: soccer | S29: Paris | T29: Paris | U29: Paris | V29: 1 | W29: 1 | X29: 0 | Y29: Best team | Z29: like | AA29: like | AB29: dislike | AC29: like | AD29: dislike | AE29: * | AF29: like | AG29: like | AH29: * | AI29: like | AJ29: like | AK29: like | AL29: like | AM29: like | AN29: * | AO29: like | AP29: like | AQ29: * | AR29: 0 | AS29: 0 | AT29: 0 | AU29: 1 | AV29: * | AW29: 1 | AX29: 0 | AY29: * | AZ29: 0 | BA29: 1 | BB29: 0 | BC29: * | BD29: 0 | BE29: 1 | BF29: * | BG29: 1 | BH29: 0 | BI29: * | BJ29: 0 | BK29: 1 | BL29: * | BM29: 0 | BN29: * | BO29: 1 | BP29: 1 | BQ29: * | BR29: * | BS29: 1 | BT29: 0 | BU29: * | BV29: * | BW29: * | BX29: * | BY29: 0 | BZ29: * | CA29: * | CB29: B | CC29: A | CD29: B | CE29: A | CF29: B | CG29: A | CH29: NO | CI29: B | CJ29: A | CK29: NO | CL29: B | CM29: A | CN29: NO | CO29: B | CP29: A
A30: M4 | B30: 7 | C30: 40876 | D30: two stage | E30: 1993 | F30: Economics | G30: French | H30: No | I30: Fair | J30: Defect | K30: Distrust | L30: PS | M30: Catholicism | N30: St Claude | O30: 2 | P30: 2 | Q30: * | R30: soccer | S30: Brazil | T30: Barca | U30: Toulouse | V30: 1 | W30: 2 | X30: 7 | Y30: Best team | Z30: like | AA30: like | AB30: like | AC30: like | AD30: like | AE30: like | AF30: * | AG30: like | AH30: * | AI30: like | AJ30: like | AK30: like | AL30: like | AM30: like | AN30: like | AO30: * | AP30: like | AQ30: * | AR30: 1 | AS30: 1 | AT30: 1 | AU30: 1 | AV30: 1 | AW30: * | AX30: 1 | AY30: * | AZ30: 1 | BA30: 1 | BB30: 1 | BC30: 1 | BD30: * | BE30: 1 | BF30: * | BG30: 1 | BH30: 1 | BI30: 1 | BJ30: * | BK30: 1 | BL30: * | BM30: 1 | BN30: 1 | BO30: * | BP30: 1 | BQ30: * | BR30: 1 | BS30: * | BT30: 1 | BU30: * | BV30: * | BW30: 1 | BX30: * | BY30: * | BZ30: * | CA30: * | CB30: B | CC30: B | CD30: B | CE30: B | CF30: B | CG30: B | CH30: YES | CI30: B | CJ30: B | CK30: NO | CL30: B | CM30: B | CN30: NO | CO30: B | CP30: B
A31: M4 | B31: 8 | C31: 40876 | D31: two stage | E31: 1993 | F31: Economics | G31: French | H31: No | I31: Fair | J31: Don't know | K31: Distrust | L31: PS | M31: Other | N31: Caen | O31: 5 | P31: 2 | Q31: * | R31: team sports, snowboard | S31: Toulouse | T31: OM | U31: Toulouse | V31: 1 | W31: 1 | X31: 6 | Y31: indifferent | Z31: like | AA31: like | AB31: like | AC31: like | AD31: indifferent | AE31: like | AF31: like | AG31: * | AH31: * | AI31: like | AJ31: like | AK31: like | AL31: like | AM31: indifferent | AN31: like | AO31: like | AP31: * | AQ31: * | AR31: 0 | AS31: 0 | AT31: 0 | AU31: 0 | AV31: 0 | AX31: * | AY31: * | AZ31: 1 | BA31: 0 | BB31: 0 | BC31: 0 | BD31: 0 | BE31: * | BF31: * | BG31: 0 | BH31: 0 | BI31: 0 | BJ31: 0 | BK31: * | BL31: * | BM31: 0 | BN31: 0 | BO31: 0 | BP31: * | BQ31: * | BR31: 0 | BS31: 0 | BT31: * | BU31: * | BV31: 0 | BW31: * | BX31: * | BY31: * | BZ31: * | CA31: * | CB31: A | CC31: B | CD31: A | CE31: B | CF31: A | CG31: B | CH31: NO | CI31: A | CJ31: B | CK31: NO | CL31: A | CM31: B | CN31: NO | CO31: A | CP31: B
A32: M5 | B32: 1 | C32: 40876 | D32: two stage | E32: 1990 | F32: Law | G32: French | H32: No | I32: Fair | J32: Defect | K32: Trust | L32: PS | M32: Other | N32: Toulouse | O32: 2 | P32: 2 | Q32: * | R32: Handball | S32: * | T32: TFC | U32: Toulouse | V32: 2 | W32: 2 | X32: 2 | Y32: Friends | Z32: * | AA32: like | AB32: like a lot | AC32: indifferent | AD32: like a lot | AE32: indifferent | AF32: dislike | AG32: * | AH32: * | AI32: * | AJ32: like | AK32: like a lot | AL32: indifferent | AM32: like a lot | AN32: indifferent | AO32: like | AP32: * | AQ32: * | AR32: * | AS32: * | AT32: * | AU32: * | AV32: * | AW32: * | AX32: * | AY32: * | AZ32: 1 | BA32: 0 | BB32: 0 | BC32: 0 | BD32: 0 | BE32: * | BF32: * | BG32: 0 | BH32: 1 | BI32: 0 | BJ32: 0 | BK32: * | BL32: * | BM32: 0 | BN32: 0 | BO32: 0 | BP32: * | BQ32: * | BR32: 0 | BS32: 0 | BT32: * | BU32: * | BV32: 0 | BW32: * | BX32: * | BY32: * | BZ32: * | CA32: * | CB32: B | CC32: B | CD32: B | CE32: B | CF32: B | CG32: B | CH32: YES | CI32: B | CJ32: B | CK32: YES | CL32: B | CM32: B | CN32: NO | CO32: B | CP32: B
A33: M5 | B33: 2 | C33: 40876 | D33: two stage | E33: 1989 | F33: Law | G33: French | H33: No | I33: don't know | J33: Cooperate | K33: Distrust | L33: Other | M33: Other | N33: Toulouse | O33: 1 | P33: 0 | Q33: * | R33: soccer | S33: * | T33: national team | U33: Toulouse | V33: 1 | W33: 0 | X33: 1 | Y33: indifferent | Z33: like | AA33: * | AB33: like | AC33: like | AD33: like | AE33: like | AF33: indifferent | AG33: * | AH33: * | AI33: like | AJ33: * | AK33: like | AL33: like | AM33: like | AN33: like | AO33: like | AP33: * | AQ33: * | AR33: * | AS33: 1 | AT33: 0 | AU33: 1 | AV33: 0 | AW33: 0 | AX33: * | AY33: * | AZ33: * | BA33: * | BB33: * | BC33: * | BD33: * | BE33: * | BF33: * | BG33: 0 | BH33: 1 | BI33: 0 | BJ33: 0 | BK33: * | BL33: * | BM33: 0 | BN33: 0 | BO33: 0 | BP33: * | BQ33: * | BR33: 0 | BS33: 0 | BT33: * | BU33: * | BV33: 0 | BW33: * | BX33: * | BY33: * | BZ33: * | CA33: * | CB33: B | CC33: B | CD33: A | CE33: B | CF33: B | CG33: A | CH33: YES | CI33: A | CJ33: A | CK33: YES | CL33: B | CM33: B | CN33: NO | CO33: A | CP33: B
A34: M5 | B34: 3 | C34: 40876 | D34: two stage | E34: 1987 | F34: Law | G34: French | H34: No | I34: don't know | J34: Cooperate | K34: Trust | L34: PCF | M34: Catholicism | N34: Villeneuve/lot | O34: 2 | P34: 0 | Q34: * | R34: running | S34: * | T34: Bordeaux | U34: Agen | V34: 1 | W34: 1 | X34: 1 | Y34: Friends | Z34: like | AA34: like a lot | AB34: * | AC34: indifferent | AD34: like | AE34: indifferent | AF34: indifferent | AG34: * | AH34: * | AI34: like | AJ34: like a lot | AK34: * | AL34: indifferent | AM34: like | AN34: indifferent | AO34: indifferent | AP34: * | AQ34: * | AR34: 0 | AS34: * | AT34: 0 | AU34: 1 | AV34: 0 | AW34: 0 | AX34: * | AY34: * | AZ34: * | BA34: 0 | BB34: 0 | BC34: 0 | BD34: 0 | BE34: * | BF34: * | BG34: * | BH34: * | BI34: * | BJ34: * | BK34: * | BL34: * | BM34: 0 | BN34: 0 | BO34: 0 | BP34: * | BQ34: * | BR34: 0 | BS34: 0 | BT34: * | BU34: * | BV34: 0 | BW34: * | BX34: * | BY34: * | BZ34: * | CA34: * | CB34: B | CC34: B | CD34: A | CE34: B | CF34: A | CG34: B | CH34: NO | CI34: B | CJ34: B | CK34: NO | CL34: A | CM34: B | CN34: NO | CO34: A | CP34: B
A35: M5 | B35: 4 | C35: 40876 | D35: two stage | E35: 1993 | F35: Politics | G35: French | H35: No | I35: Unfair | J35: Cooperate | K35: Trust | L35: EELV | M35: Bouddhism | N35: Groix | O35: 2 | P35: 2 | Q35: * | R35: climbing, tennis, swimming | S35: * | T35: * | U35: * | V35: 0 | W35: 0 | X35: 0 | Y35: indifferent | Z35: like | AA35: like | AB35: like | AC35: * | AD35: indifferent | AE35: indifferent | AF35: like | AG35: * | AH35: * | AI35: like | AJ35: like | AK35: like | AL35: * | AM35: like | AN35: indifferent | AO35: like | AP35: * | AQ35: * | AR35: 1 | AS35: 1 | AT35: * | AU35: 1 | AV35: 0 | AW35: 0 | AX35: * | AY35: * | AZ35: 1 | BA35: * | BB35: 1 | BC35: 0 | BD35: 0 | BE35: * | BF35: * | BG35: * | BH35: 1 | BI35: 0 | BJ35: 0 | BK35: * | BL35: * | BM35: * | BN35: * | BO35: * | BP35: * | BQ35: * | BR35: 0 | BS35: 0 | BT35: * | BU35: * | BV35: 0 | BW35: * | BX35: * | BY35: * | BZ35: * | CA35: * | CB35: B | CC35: B | CD35: B | CE35: B | CF35: B | CG35: B | CH35: YES | CI35: B | CJ35: B | CK35: YES | CL35: B | CM35: B | CN35: YES | CO35: B | CP35: B
A36: M5 | B36: 5 | C36: 40876 | D36: two stage | E36: 1992 | F36: AES | G36: French | H36: No | I36: Fair | J36: Defect | K36: Distrust | L36: UMP | M36: Islam | N36: Dola | O36: 2 | P36: 0 | Q36: * | R36: soccer, judo | S36: Toulouse | T36: Lyon | U36: Toulouse | V36: 2 | W36: 1 | X36: 2 | Y36: Friends | Z36: like | AA36: like | AB36: like | AC36: indifferent | AD36: * | AE36: indifferent | AF36: indifferent | AG36: * | AH36: * | AI36: like | AJ36: like | AK36: like | AL36: indifferent | AM36: * | AN36: indifferent | AO36: indifferent | AP36: * | AQ36: * | AR36: 1 | AS36: 1 | AT36: 0 | AU36: * | AV36: 0 | AW36: 0 | AX36: * | AY36: * | AZ36: 1 | BA36: 0 | BB36: * | BC36: 0 | BD36: 0 | BE36: * | BF36: * | BG36: 0 | BH36: * | BI36: 0 | BJ36: 0 | BK36: * | BL36: * | BM36: * | BN36: 0 | BO36: 0 | BP36: * | BQ36: * | BR36: * | BS36: * | BT36: * | BU36: * | BV36: 0 | BW36: * | BX36: * | BY36: * | BZ36: * | CA36: * | CB36: A | CC36: A | CD36: A | CE36: A | CF36: A | CG36: A | CH36: YES | CI36: B | CJ36: B | CK36: YES | CL36: A | CM36: A | CN36: NO | CO36: B | CP36: A
A37: M5 | B37: 6 | C37: 40883 | D37: two stage | E37: 1985 | F37: Law | G37: Bulgarian | H37: Yes | I37: Unfair | J37: Defect | K37: Distrust | L37: Other | M37: Other | N37: Sofia (Bulgaria) | O37: 6 | P37: 0 | Q37: * | R37: soccer, tennir, swimming | S37: national team | T37: Barca, Levski | U37: Toulouse | V37: 6 | W37: 1 | X37: 0 | Y37: Friends | Z37: indifferent | AA37: like | AB37: like | AC37: indifferent | AD37: indifferent | AE37: * | AF37: dislike | AG37: * | AH37: * | AI37: indifferent | AJ37: indifferent | AK37: like | AL37: indifferent | AM37: indifferent | AN37: like a lot | AO37: dislike | AP37: * | AQ37: * | AR37: 1 | AS37: 0 | AT37: 0 | AU37: 0 | AV37: * | AW37: 0 | AX37: * | AY37: * | AZ37: 0 | BA37: 0 | BB37: 0 | BC37: * | BD37: 0 | BE37: * | BF37: * | BG37: 0 | BH37: 0 | BI37: * | BJ37: 0 | BK37: * | BL37: * | BM37: 0 | BN37: * | BO37: 0 | BP37: * | BQ37: * | BR37: * | BS37: 0 | BT37: * | BU37: * | BV37: * | BW37: * | BX37: * | BY37: * | BZ37: * | CA37: * | CB37: A | CC37: A | CD37: A | CE37: A | CF37: A | CG37: A | CH37: YES | CI37: A | CJ37: A | CK37: YES | CL37: A | CM37: B | CN37: YES | CO37: A | CP37: A
A38: M5 | B38: 7 | C38: 40876 | D38: two stage | E38: 1988 | F38: Law | G38: German | H38: Yes | I38: don't know | J38: Defect | K38: don't know | L38: EELV | M38: Protestantism | N38: Berlin (Germany) | O38: 4 | P38: 0 | Q38: tennis | R38: * | S38: France | T38: Berlin | U38: Toulouse | V38: 0 | W38: 0 | X38: 0 | Y38: indifferent | Z38: indifferent | AA38: like | AB38: like | AC38: like | AD38: like | AE38: like | AG38: * | AH38: * | AI38: indifferent | AJ38: indifferent | AK38: indifferent | AL38: like | AM38: indifferent | AN38: like | AO38: * | AP38: * | AQ38: * | AR38: 1 | AS38: 1 | AT38: 0 | AU38: 1 | AV38: 0 | AW38: * | AX38: * | AY38: * | AZ38: 1 | BA38: 0 | BB38: 0 | BC38: 0 | BD38: * | BE38: * | BF38: * | BG38: 0 | BH38: 0 | BI38: 0 | BJ38: * | BK38: * | BL38: * | BM38: 0 | BN38: 0 | BO38: * | BP38: * | BQ38: * | BR38: 0 | BS38: * | BT38: * | BU38: * | BV38: * | BW38: * | BX38: * | BY38: * | BZ38: * | CA38: * | CB38: B | CC38: B | CD38: B | CE38: B | CF38: A | CG38: B | CH38: YES | CI38: B | CJ38: B | CK38: YES | CL38: A | CM38: B | CN38: YES | CO38: A | CP38: B
A39: F1 | B39: 1 | C39: 40876 | D39: one shot | E39: 1989 | F39: Politics | G39: French | H39: No | I39: don't know | J39: Defect | K39: Distrust | L39: PS | M39: Other | N39: Quimper | O39: 13 | P39: 4 | Q39: * | R39: running, beach volley | S39: Spacers, Nationa team | T39: * | U39: Toulouse, national team | V39: 5 | W39: 5 | X39: 5 | Y39: Best team | Z39: * | AA39: like a lot | AB39: * | AC39: like a lot | AD39: like | AE39: like a lot | AF39: like | AG39: like | AH39: like a lot | AI39: * | AJ39: like a lot | AK39: * | AL39: like a lot | AM39: like | AN39: like a lot | AO39: like | AP39: like | AQ39: like a lot | AR39: * | AS39: * | AT39: * | AU39: * | AV39: * | AW39: * | AX39: * | AY39: * | AZ39: * | BA39: 1 | BB39: 0 | BC39: 1 | BD39: 0 | BE39: 0 | BF39: 1 | BG39: * | BH39: * | BI39: * | BJ39: * | BK39: * | BL39: * | BM39: 1 | BN39: 1 | BO39: 0 | BP39: 0 | BQ39: 1 | BR39: 0 | BS39: 0 | BT39: 0 | BU39: 0 | BV39: 0 | BW39: 0 | BX39: 1 | BY39: 0 | BZ39: 0 | CA39: 0 | CB39: B | CC39: B | CD39: B | CE39: B | CF39: B | CG39: B | CH39: YES | CI39: B | CJ39: B | CK39: YES | CL39: B | CM39: B | CN39: YES | CO39: B | CP39: B
A40: F1 | B40: 2 | C40: 40876 | D40: one shot | E40: 1989 | F40: Politics | G40: French | H40: Yes | I40: don't know | J40: Don't know | K40: don't know | L40: PS | M40: Other | N40: La rochelle | O40: 12 | P40: * | Q40: * | R40: running | S40: * | T40: * | U40: * | V40: 5 | W40: 5 | X40: 2 | Y40: Best team | Z40: like a lot | AA40: * | AB40: * | AC40: like a lot | AD40: like | AE40: like a lot | AF40: like | AG40: like | AH40: like a lot | AI40: like a lot | AJ40: * | AK40: * | AL40: like a lot | AM40: like | AN40: like a lot | AO40: like | AP40: like | AQ40: like a lot | AR40: * | AS40: * | AT40: 1 | AU40: 0 | AV40: 1 | AW40: 0 | AX40: 0 | AY40: 1 | AZ40: * | BA40: * | BB40: * | BC40: * | BD40: * | BE40: * | BF40: * | BG40: * | BH40: * | BI40: * | BJ40: * | BK40: * | BL40: * | BM40: 0 | BN40: 1 | BO40: 0 | BP40: 0 | BQ40: 1 | BR40: 0 | BS40: 0 | BT40: 0 | BU40: 0 | BV40: 0 | BW40: 0 | BX40: 1 | BY40: 0 | BZ40: 0 | CA40: 0 | CB40: B | CC40: B | CD40: B | CE40: B | CF40: B | CG40: B | CH40: YES | CI40: B | CJ40: B | CK40: YES | CL40: B | CM40: B | CN40: NO | CO40: B | CP40: B
...

Sheet transform
A1: Group | B1: Gender | C1: Id | D1: Participation_date | E1: First_game | F1: Birth_year | G1: study | H1: mother_tongue | I1: General_Info_Q1 | J1: General_Info_Q2 | K1: General_Info_Q3 | L1: General_Info_Q4 | M1: General_Info_Q5 | N1: General_Info_Q6 | O1: General_Info_Q71 | P1: General_Info_Q72 | Q1: Volleyball_Q1 | R1: Volleyball_Q2 | S1: Volleyball_Q3 | T1: Volleyball_Q4 | U1: Volleyball_Q5 | V1: Volleyball_Q6 | W1: Volleyball_Q7 | X1: Team_Q1 | Y1: Team_Q2 | Z1: Team_Q3 | AA1: Team_Q4 | AB1: Team_Q5_1 | AC1: Team_Q5_2 | AD1: Team_Q5_3 | AE1: Team_Q5_4 | AF1: Team_Q5_5 | AG1: Team_Q5_6 | AH1: Team_Q5_7 | AI1: Team_Q5_8 | AJ1: Team_Q5_9 | AK1: Team_Q5_like1 | AL1: Team_Q5_like2 | AM1: Team_Q5_like3 | AN1: Team_Q5_like4 | AO1: Team_Q5_Ties1 | AP1: Team_Q5_Ties2 | AQ1: Team_Q5_Ties3 | AR1: Team_Q5_Ties4 | AS1: Team_Q5_Ties5 | AT1: Team_Q5_Ties6 | AU1: Team_Q5_Ties7 | AV1: Team_Q5_Ties8 | AW1: Team_Q5_Ties9 | AX1: Team_Q6_1 | AY1: Team_Q6_2 | AZ1: Team_Q6_3 | BA1: Team_Q6_4 | BB1: Team_Q6_5 | BC1: Team_Q6_6 | BD1: Team_Q6_7 | BE1: Team_Q6_8 | BF1: Team_Q6_9 | BG1: Team_Q6_like1 | BH1: Team_Q6_like2 | BI1: Team_Q6_like3 | BJ1: Team_Q6_like4 | BK1: Team_Q56_B1 | BL1: Team_Q56_B2 | BM1: Team_Q56_B3 | BN1: Team_Q56_B4 | BO1: Team_Q56_B5 | BP1: Team_Q56_B6 | BQ1: Team_Q56_B7 | BR1: Team_Q56_B8 | BS1: Team_Q56_B9 | BT1: Team_Q7_1 | BU1: Team_Q7_2 | BV1: Team_Q7_3 | BW1: Team_Q7_4 | BX1: Team_Q7_5 | BY1: Team_Q7_6 | BZ1: Team_Q7_7 | CA1: Team_Q7_8 | CB1: Team_Q7_9 | CC1: T1_1_AB | CD1: T1_2_AB | CE1: V1_1_AB | CF1: V1_2_AB | CG1: S1_1_AB | CH1: S1_2_AB | CI1: T2_1_IN | CJ1: T2_1_AB | CK1: T2_2_AB | CL1: V2_1_IN | CM1: V2_1_AB | CN1: V2_2_AB | CO1: S2_1_IN | CP1: S2_1_AB | CQ1: S2_2_AB
A2: 1 | B2: 1 | C2: 1 | D2: 40876 | E2: 1 | F2: 1991 | G2: 1 | H2: 1 | I2: 0 | J2: 1 | K2: 1 | L2: 2 | M2: 3 | N2: 0 | O2: 2 | P2: 1 | Q2: 8 | R2: 10 | S2: 0 | T2: 1 | U2: 1 | V2: 2 | W2: 1 | X2: 2 | Y2: 2 | Z2: 8 | AA2: 0 | AC2: 4 | AD2: 4 | AE2: 4 | AF2: 3 | AG2: 4 | AH2: 3 | AI2: 3 | AK2: =COUNTIF(AB2:AJ2,1) -> 0 | AL2: =COUNTIF(AB2:AJ2,2) -> 0 | AM2: =COUNTIF(AB2:AJ2,3) -> 3 | AN2: =COUNTIF(AB2:AJ2,4) -> 4 | AO2: 0 | AP2: 1 | AQ2: 1 | AR2: 1 | AS2: 1 | AT2: 1 | AV2: 1 | AW2: 0 | AY2: 4 | AZ2: 4 | BA2: 4 | BB2: 3 | BC2: 4 | BD2: 3 | BE2: 3 | BG2: =COUNTIF(AX2:BF2,1) -> 0 | BH2: =COUNTIF(AX2:BF2,2) -> 0 | BI2: =COUNTIF(AX2:BF2,3) -> 3 | BJ2: =COUNTIF(AX2:BF2,4) -> 4 | BK2: =IF(AND(OR(AB2=3,AB2=4),OR(AX2=3,AX2=4)),1,0) -> 0 | BL2: =IF(AND(OR(AC2=3,AC2=4),OR(AY2=3,AY2=4)),1,0) -> 1 | BM2: =IF(AND(OR(AD2=3,AD2=4),OR(AZ2=3,AZ2=4)),1,0) -> 1 | BN2: =IF(AND(OR(AE2=3,AE2=4),OR(BA2=3,BA2=4)),1,0) -> 1 | BO2: =IF(AND(OR(AF2=3,AF2=4),OR(BB2=3,BB2=4)),1,0) -> 1 | BP2: =IF(AND(OR(AG2=3,AG2=4),OR(BC2=3,BC2=4)),1,0) -> 1 | BQ2: =IF(AND(OR(AH2=3,AH2=4),OR(BD2=3,BD2=4)),1,0) -> 1 | BR2: =IF(AND(OR(AI2=3,AI2=4),OR(BE2=3,BE2=4)),1,0) -> 1 | BS2: =IF(AND(OR(AJ2=3,AJ2=4),OR(BF2=3,BF2=4)),1,0) -> 0 | BU2: =SUM(Raw!AR2:AR9) -> 4 | BV2: =SUM(Raw!AS2:AS9) -> 5 | BW2: =SUM(Raw!AT2:AT9) -> 3 | BX2: =SUM(Raw!AU2:AU9) -> 3 | BY2: =SUM(Raw!AV2:AV9) -> 6 | BZ2: =SUM(Raw!AW2:AW9) -> 0 | CA2: =SUM(Raw!AX2:AX9) -> 2 | CC2: 2 | CD2: 2 | CE2: 2 | CF2: 2 | CG2: 2 | CH2: 2 | CI2: 1 | CJ2: 2 | CK2: 2 | CL2: 1 | CM2: 1 | CN2: 2 | CO2: 1 | CP2: 2 | CQ2: 1
A3: 1 | B3: 1 | C3: 2 | D3: 40876 | E3: 1 | F3: 1988 | G3: 4 | H3: 1 | I3: 0 | J3: 2 | K3: 1 | L3: 2 | M3: 3 | N3: 2 | O3: 0 | P3: 1 | Q3: 3 | R3: 8 | S3: 0 | T3: 5 | U3: 2 | V3: 1 | W3: 1 | X3: 1 | Y3: 1 | Z3: 5 | AA3: 2 | AB3: 4 | AD3: 4 | AE3: 3 | AF3: 4 | AG3: 4 | AH3: 3 | AI3: 3 | AK3: =COUNTIF(AB3:AJ3,1) -> 0 | AL3: =COUNTIF(AB3:AJ3,2) -> 0 | AM3: =COUNTIF(AB3:AJ3,3) -> 3 | AN3: =COUNTIF(AB3:AJ3,4) -> 4 | AO3: 1 | AP3: 0 | AQ3: 1 | AR3: 1 | AS3: 1 | AT3: 1 | AV3: 1 | AW3: 0 | AX3: 3 | AZ3: 4 | BA3: 3 | BB3: 3 | BC3: 4 | BD3: 2 | BE3: 3 | BG3: =COUNTIF(AX3:BF3,1) -> 0 | BH3: =COUNTIF(AX3:BF3,2) -> 1 | BI3: =COUNTIF(AX3:BF3,3) -> 4 | BJ3: =COUNTIF(AX3:BF3,4) -> 2 | BK3: =IF(AND(OR(AB3=3,AB3=4),OR(AX3=3,AX3=4)),1,0) -> 1 | BL3: =IF(AND(OR(AC3=3,AC3=4),OR(AY3=3,AY3=4)),1,0) -> 0 | BM3: =IF(AND(OR(AD3=3,AD3=4),OR(AZ3=3,AZ3=4)),1,0) -> 1 | BN3: =IF(AND(OR(AE3=3,AE3=4),OR(BA3=3,BA3=4)),1,0) -> 1 | BO3: =IF(AND(OR(AF3=3,AF3=4),OR(BB3=3,BB3=4)),1,0) -> 1 | BP3: =IF(AND(OR(AG3=3,AG3=4),OR(BC3=3,BC3=4)),1,0) -> 1 | BQ3: =IF(AND(OR(AH3=3,AH3=4),OR(BD3=3,BD3=4)),1,0) -> 0 | BR3: =IF(AND(OR(AI3=3,AI3=4),OR(BE3=3,BE3=4)),1,0) -> 1 | BS3: =IF(AND(OR(AJ3=3,AJ3=4),OR(BF3=3,BF3=4)),1,0) -> 0 | BT3: =SUM(Raw!AR2:AR9) -> 4 | BV3: =SUM(Raw!AZ2:AZ9) -> 5 | BW3: =SUM(Raw!BA2:BA9) -> 2 | BX3: =SUM(Raw!BB2:BB9) -> 2 | BY3: =SUM(Raw!BC2:BC9) -> 5 | BZ3: =SUM(Raw!BD2:BD9) -> 0 | CA3: =SUM(Raw!BE2:BE9) -> 3 | CC3: 2 | CD3: 2 | CE3: 1 | CF3: 2 | CG3: 1 | CH3: 2 | CI3: 1 | CJ3: 1 | CK3: 2 | CL3: 1 | CM3: 1 | CN3: 2 | CO3: 1 | CP3: 1 | CQ3: 2
A4: 1 | B4: 1 | C4: 3 | D4: 40876 | E4: 1 | F4: 1987 | G4: 2 | H4: 1 | I4: 1 | J4: 1 | K4: 1 | L4: 1 | M4: 1 | N4: 3 | O4: 4 | P4: 0 | Q4: 12 | R4: 10 | S4: 1 | T4: 4 | U4: 2 | V4: 0 | W4: 1 | X4: 3 | Y4: 3 | Z4: 5 | AA4: 0 | AB4: 4 | AC4: 4 | AE4: 4 | AF4: 4 | AG4: 4 | AH4: 4 | AI4: 4 | AK4: =COUNTIF(AB4:AJ4,1) -> 0 | AL4: =COUNTIF(AB4:AJ4,2) -> 0 | AM4: =COUNTIF(AB4:AJ4,3) -> 0 | AN4: =COUNTIF(AB4:AJ4,4) -> 7 | AO4: 1 | AP4: 1 | AQ4: 0 | AR4: 1 | AS4: 1 | AT4: 1 | AV4: 1 | AW4: 0 | AX4: 3 | AY4: 4 | BA4: 3 | BB4: 4 | BC4: 3 | BD4: 3 | BE4: 3 | BG4: =COUNTIF(AX4:BF4,1) -> 0 | BH4: =COUNTIF(AX4:BF4,2) -> 0 | BI4: =COUNTIF(AX4:BF4,3) -> 5 | BJ4: =COUNTIF(AX4:BF4,4) -> 2 | BK4: =IF(AND(OR(AB4=3,AB4=4),OR(AX4=3,AX4=4)),1,0) -> 1 | BL4: =IF(AND(OR(AC4=3,AC4=4),OR(AY4=3,AY4=4)),1,0) -> 1 | BM4: =IF(AND(OR(AD4=3,AD4=4),OR(AZ4=3,AZ4=4)),1,0) -> 0 | BN4: =IF(AND(OR(AE4=3,AE4=4),OR(BA4=3,BA4=4)),1,0) -> 1 | BO4: =IF(AND(OR(AF4=3,AF4=4),OR(BB4=3,BB4=4)),1,0) -> 1 | BP4: =IF(AND(OR(AG4=3,AG4=4),OR(BC4=3,BC4=4)),1,0) -> 1 | BQ4: =IF(AND(OR(AH4=3,AH4=4),OR(BD4=3,BD4=4)),1,0) -> 1 | BR4: =IF(AND(OR(AI4=3,AI4=4),OR(BE4=3,BE4=4)),1,0) -> 1 | BS4: =IF(AND(OR(AJ4=3,AJ4=4),OR(BF4=3,BF4=4)),1,0) -> 0 | BT4: =SUM(Raw!AS2:AS9) -> 5 | BU4: =SUM(Raw!AZ2:AZ9) -> 5 | BW4: =SUM(Raw!BG2:BG9) -> 5 | BX4: =SUM(Raw!BH2:BH9) -> 4 | BY4: =SUM(Raw!BI2:BI9) -> 3 | BZ4: =SUM(Raw!BJ2:BJ9) -> 2 | CA4: =SUM(Raw!BK2:BK9) -> 3 | CC4: 1 | CD4: 2 | CE4: 2 | CF4: 2 | CG4: 2 | CH4: 2 | CI4: 0 | CJ4: 2 | CK4: 2 | CL4: 0 | CM4: 2 | CN4: 1 | CO4: 0 | CP4: 2 | CQ4: 1
A5: 1 | B5: 1 | C5: 4 | D5: 40876 | E5: 1 | F5: 1986 | G5: 4 | H5: 2 | I5: 1 | J5: 1 | K5: 2 | L5: 2 | M5: 5 | N5: 2 | O5: 5 | P5: 1 | Q5: 9 | R5: 2 | S5: 0 | T5: 1 | U5: 2 | V5: 2 | W5: 1 | X5: 2 | Y5: 2 | Z5: 3 | AA5: 2 | AB5: 3 | AC5: 3 | AD5: 4 | AF5: 4 | AG5: 3 | AH5: 3 | AI5: 3 | AK5: =COUNTIF(AB5:AJ5,1) -> 0 | AL5: =COUNTIF(AB5:AJ5,2) -> 0 | AM5: =COUNTIF(AB5:AJ5,3) -> 5 | AN5: =COUNTIF(AB5:AJ5,4) -> 2 | AO5: 1 | AP5: 1 | AQ5: 1 | AR5: 0 | AS5: 1 | AT5: 1 | AV5: 1 | AW5: 0 | AX5: 3 | AY5: 3 | AZ5: 3 | BB5: 3 | BC5: 3 | BD5: 3 | BE5: 3 | BG5: =COUNTIF(AX5:BF5,1) -> 0 | BH5: =COUNTIF(AX5:BF5,2) -> 0 | BI5: =COUNTIF(AX5:BF5,3) -> 7 | BJ5: =COUNTIF(AX5:BF5,4) -> 0 | BK5: =IF(AND(OR(AB5=3,AB5=4),OR(AX5=3,AX5=4)),1,0) -> 1 | BL5: =IF(AND(OR(AC5=3,AC5=4),OR(AY5=3,AY5=4)),1,0) -> 1 | BM5: =IF(AND(OR(AD5=3,AD5=4),OR(AZ5=3,AZ5=4)),1,0) -> 1 | BN5: =IF(AND(OR(AE5=3,AE5=4),OR(BA5=3,BA5=4)),1,0) -> 0 | BO5: =IF(AND(OR(AF5=3,AF5=4),OR(BB5=3,BB5=4)),1,0) -> 1 | BP5: =IF(AND(OR(AG5=3,AG5=4),OR(BC5=3,BC5=4)),1,0) -> 1 | BQ5: =IF(AND(OR(AH5=3,AH5=4),OR(BD5=3,BD5=4)),1,0) -> 1 | BR5: =IF(AND(OR(AI5=3,AI5=4),OR(BE5=3,BE5=4)),1,0) -> 1 | BS5: =IF(AND(OR(AJ5=3,AJ5=4),OR(BF5=3,BF5=4)),1,0) -> 0 | BT5: =SUM(Raw!AT2:AT9) -> 3 | BU5: =SUM(Raw!BA2:BA9) -> 2 | BV5: =SUM(Raw!BG2:BG9) -> 5 | BX5: =SUM(Raw!BM2:BM9) -> 2 | BY5: =SUM(Raw!BN2:BN9) -> 1 | BZ5: =SUM(Raw!BO2:BO9) -> 0 | CA5: =SUM(Raw!BP2:BP9) -> 2 | CC5: 1 | CD5: 1 | CE5: 1 | CF5: 2 | CG5: 1 | CH5: 2 | CI5: 1 | CJ5: 1 | CK5: 1 | CL5: 1 | CM5: 2 | CN5: 1 | CO5: 1 | CP5: 1 | CQ5: 2
A6: 1 | B6: 1 | C6: 5 | D6: 40876 | E6: 1 | F6: 1989 | G6: 3 | H6: 1 | I6: 0 | J6: 1 | K6: 1 | L6: 1 | M6: 3 | N6: 0 | O6: 2 | P6: 1 | Q6: 5 | R6: 2 | S6: 0 | T6: 3 | U6: 1 | V6: 2 | W6: 1 | X6: 3 | Y6: 3 | Z6: 7 | AA6: 0 | AB6: 4 | AC6: 4 | AD6: 4 | AE6: 4 | AG6: 4 | AH6: 4 | AI6: 4 | AK6: =COUNTIF(AB6:AJ6,1) -> 0 | AL6: =COUNTIF(AB6:AJ6,2) -> 0 | AM6: =COUNTIF(AB6:AJ6,3) -> 0 | AN6: =COUNTIF(AB6:AJ6,4) -> 7 | AO6: 1 | AP6: 1 | AQ6: 1 | AR6: 1 | AS6: 0 | AT6: 1 | AV6: 1 | AW6: 0 | AX6: 4 | AY6: 4 | AZ6: 4 | BA6: 4 | BC6: 4 | BD6: 4 | BE6: 4 | BG6: =COUNTIF(AX6:BF6,1) -> 0 | BH6: =COUNTIF(AX6:BF6,2) -> 0 | BI6: =COUNTIF(AX6:BF6,3) -> 0 | BJ6: =COUNTIF(AX6:BF6,4) -> 7 | BK6: =IF(AND(OR(AB6=3,AB6=4),OR(AX6=3,AX6=4)),1,0) -> 1 | BL6: =IF(AND(OR(AC6=3,AC6=4),OR(AY6=3,AY6=4)),1,0) -> 1 | BM6: =IF(AND(OR(AD6=3,AD6=4),OR(AZ6=3,AZ6=4)),1,0) -> 1 | BN6: =IF(AND(OR(AE6=3,AE6=4),OR(BA6=3,BA6=4)),1,0) -> 1 | BO6: =IF(AND(OR(AF6=3,AF6=4),OR(BB6=3,BB6=4)),1,0) -> 0 | BP6: =IF(AND(OR(AG6=3,AG6=4),OR(BC6=3,BC6=4)),1,0) -> 1 | BQ6: =IF(AND(OR(AH6=3,AH6=4),OR(BD6=3,BD6=4)),1,0) -> 1 | BR6: =IF(AND(OR(AI6=3,AI6=4),OR(BE6=3,BE6=4)),1,0) -> 1 | BS6: =IF(AND(OR(AJ6=3,AJ6=4),OR(BF6=3,BF6=4)),1,0) -> 0 | BT6: =SUM(Raw!AU2:AU9) -> 3 | BU6: =SUM(Raw!BB2:BB9) -> 2 | BV6: =SUM(Raw!BH2:BH9) -> 4 | BW6: =SUM(Raw!BM2:BM9) -> 2 | BY6: =SUM(Raw!BR2:BR9) -> 3 | BZ6: =SUM(Raw!BS2:BS9) -> 2 | CA6: =SUM(Raw!BT2:BT9) -> 1 | CC6: 2 | CD6: 2 | CE6: 2 | CF6: 2 | CG6: 2 | CH6: 2 | CI6: 1 | CJ6: 2 | CK6: 2 | CL6: 1 | CM6: 2 | CN6: 2 | CO6: 1 | CP6: 2 | CQ6: 2
A7: 1 | B7: 1 | C7: 6 | D7: 40876 | E7: 1 | F7: 1984 | G7: 5 | H7: 1 | I7: 0 | J7: 2 | K7: 1 | L7: 2 | M7: 0 | N7: 0 | O7: 1 | P7: 1 | Q7: 11 | R7: 10 | S7: 1 | T7: 2 | U7: 2 | V7: 0 | W7: 2 | X7: 0 | Y7: 0 | Z7: 8 | AA7: 1 | AB7: 4 | AC7: 4 | AD7: 4 | AE7: 4 | AF7: 4 | AH7: 2 | AI7: 4 | AK7: =COUNTIF(AB7:AJ7,1) -> 0 | AL7: =COUNTIF(AB7:AJ7,2) -> 1 | AM7: =COUNTIF(AB7:AJ7,3) -> 0 | AN7: =COUNTIF(AB7:AJ7,4) -> 6 | AO7: 1 | AP7: 1 | AQ7: 1 | AR7: 1 | AS7: 1 | AT7: 0 | AV7: 1 | AW7: 0 | AX7: 4 | AY7: 4 | AZ7: 3 | BA7: 3 | BB7: 3 | BD7: 2 | BE7: 3 | BG7: =COUNTIF(AX7:BF7,1) -> 0 | BH7: =COUNTIF(AX7:BF7,2) -> 1 | BI7: =COUNTIF(AX7:BF7,3) -> 4 | BJ7: =COUNTIF(AX7:BF7,4) -> 2 | BK7: =IF(AND(OR(AB7=3,AB7=4),OR(AX7=3,AX7=4)),1,0) -> 1 | BL7: =IF(AND(OR(AC7=3,AC7=4),OR(AY7=3,AY7=4)),1,0) -> 1 | BM7: =IF(AND(OR(AD7=3,AD7=4),OR(AZ7=3,AZ7=4)),1,0) -> 1 | BN7: =IF(AND(OR(AE7=3,AE7=4),OR(BA7=3,BA7=4)),1,0) -> 1 | BO7: =IF(AND(OR(AF7=3,AF7=4),OR(BB7=3,BB7=4)),1,0) -> 1 | BP7: =IF(AND(OR(AG7=3,AG7=4),OR(BC7=3,BC7=4)),1,0) -> 0 | BQ7: =IF(AND(OR(AH7=3,AH7=4),OR(BD7=3,BD7=4)),1,0) -> 0 | BR7: =IF(AND(OR(AI7=3,AI7=4),OR(BE7=3,BE7=4)),1,0) -> 1 | BS7: =IF(AND(OR(AJ7=3,AJ7=4),OR(BF7=3,BF7=4)),1,0) -> 0 | BT7: =SUM(Raw!AV2:AV9) -> 6 | BU7: =SUM(Raw!BC2:BC9) -> 5 | BV7: =SUM(Raw!BI2:BI9) -> 3 | BW7: =SUM(Raw!BN2:BN9) -> 1 | BX7: =SUM(Raw!BR2:BR9) -> 3 | BZ7: =SUM(Raw!BV2:BV9) -> 0 | CA7: =SUM(Raw!BW2:BW9) -> 3 | CC7: 2 | CD7: 2 | CE7: 1 | CF7: 2 | CG7: 1 | CH7: 2 | CI7: 0 | CJ7: 1 | CK7: 2 | CL7: 1 | CM7: 1 | CN7: 2 | CO7: 0 | CP7: 1 | CQ7: 2
A8: 1 | B8: 1 | C8: 8 | D8: 40876 | E8: 1 | F8: 1989 | G8: 4 | H8: 1 | I8: 1 | J8: 2 | K8: 2 | L8: 2 | M8: 3 | N8: 0 | O8: 1 | P8: 0 | Q8: 8 | R8: 8 | S8: 1 | T8: 1 | U8: 1 | V8: 2 | W8: 1 | X8: 1 | Y8: 1 | Z8: 5 | AA8: 0 | AB8: 3 | AC8: 3 | AD8: 3 | AE8: 3 | AF8: 3 | AG8: 3 | AH8: 3 | AK8: =COUNTIF(AB8:AJ8,1) -> 0 | AL8: =COUNTIF(AB8:AJ8,2) -> 0 | AM8: =COUNTIF(AB8:AJ8,3) -> 7 | AN8: =COUNTIF(AB8:AJ8,4) -> 0 | AO8: 1 | AP8: 1 | AQ8: 1 | AR8: 1 | AS8: 1 | AT8: 1 | AV8: 0 | AW8: 0 | AX8: 3 | AY8: 3 | AZ8: 3 | BA8: 3 | BB8: 3 | BC8: 3 | BD8: 3 | BG8: =COUNTIF(AX8:BF8,1) -> 0 | BH8: =COUNTIF(AX8:BF8,2) -> 0 | BI8: =COUNTIF(AX8:BF8,3) -> 7 | BJ8: =COUNTIF(AX8:BF8,4) -> 0 | BK8: =IF(AND(OR(AB8=3,AB8=4),OR(AX8=3,AX8=4)),1,0) -> 1 | BL8: =IF(AND(OR(AC8=3,AC8=4),OR(AY8=3,AY8=4)),1,0) -> 1 | BM8: =IF(AND(OR(AD8=3,AD8=4),OR(AZ8=3,AZ8=4)),1,0) -> 1 | BN8: =IF(AND(OR(AE8=3,AE8=4),OR(BA8=3,BA8=4)),1,0) -> 1 | BO8: =IF(AND(OR(AF8=3,AF8=4),OR(BB8=3,BB8=4)),1,0) -> 1 | BP8: =IF(AND(OR(AG8=3,AG8=4),OR(BC8=3,BC8=4)),1,0) -> 1 | BQ8: =IF(AND(OR(AH8=3,AH8=4),OR(BD8=3,BD8=4)),1,0) -> 1 | BR8: =IF(AND(OR(AI8=3,AI8=4),OR(BE8=3,BE8=4)),1,0) -> 0 | BS8: =IF(AND(OR(AJ8=3,AJ8=4),OR(BF8=3,BF8=4)),1,0) -> 0 | BT8: =SUM(Raw!AX2:AX9) -> 2 | BU8: =SUM(Raw!BE2:BE9) -> 3 | BV8: =SUM(Raw!BK2:BK9) -> 3 | BW8: =SUM(Raw!BP2:BP9) -> 2 | BX8: =SUM(Raw!BT2:BT9) -> 1 | BY8: =SUM(Raw!BW2:BW9) -> 3 | BZ8: =SUM(Raw!BY2:BY9) -> 0 | CC8: 1 | CD8: 1 | CE8: 1 | CF8: 2 | CG8: 1 | CH8: 2 | CI8: 1 | CJ8: 1 | CK8: 2 | CL8: 1 | CM8: 1 | CN8: 2 | CO8: 0 | CP8: 1 | CQ8: 2
A9: 1 | B9: 1 | C9: 9 | D9: 40876 | E9: 1 | F9: 1989 | G9: 2 | H9: 1 | I9: 0 | J9: 1 | K9: 2 | L9: 1 | M9: 4 | N9: 0 | O9: 1 | P9: 0 | Q9: 6 | R9: 2 | S9: 0 | T9: 1 | U9: 1 | V9: 2 | W9: 1 | X9: 1 | Y9: 1 | Z9: 0 | AA9: 0 | AB9: 3 | AC9: 3 | AD9: 3 | AE9: 2 | AF9: 3 | AG9: 3 | AH9: 2 | AI9: 3 | AK9: =COUNTIF(AB9:AJ9,1) -> 0 | AL9: =COUNTIF(AB9:AJ9,2) -> 2 | AM9: =COUNTIF(AB9:AJ9,3) -> 6 | AN9: =COUNTIF(AB9:AJ9,4) -> 0 | AO9: 0 | AP9: 0 | AQ9: 0 | AR9: 0 | AS9: 0 | AT9: 0 | AV9: 0 | AW9: 0 | AX9: 3 | AY9: 3 | AZ9: 3 | BA9: 2 | BB9: 3 | BC9: 3 | BD9: 2 | BE9: 3 | BG9: =COUNTIF(AX9:BF9,1) -> 0 | BH9: =COUNTIF(AX9:BF9,2) -> 2 | BI9: =COUNTIF(AX9:BF9,3) -> 6 | BJ9: =COUNTIF(AX9:BF9,4) -> 0 | BK9: =IF(AND(OR(AB9=3,AB9=4),OR(AX9=3,AX9=4)),1,0) -> 1 | BL9: =IF(AND(OR(AC9=3,AC9=4),OR(AY9=3,AY9=4)),1,0) -> 1 | BM9: =IF(AND(OR(AD9=3,AD9=4),OR(AZ9=3,AZ9=4)),1,0) -> 1 | BN9: =IF(AND(OR(AE9=3,AE9=4),OR(BA9=3,BA9=4)),1,0) -> 0 | BO9: =IF(AND(OR(AF9=3,AF9=4),OR(BB9=3,BB9=4)),1,0) -> 1 | BP9: =IF(AND(OR(AG9=3,AG9=4),OR(BC9=3,BC9=4)),1,0) -> 1 | BQ9: =IF(AND(OR(AH9=3,AH9=4),OR(BD9=3,BD9=4)),1,0) -> 0 | BR9: =IF(AND(OR(AI9=3,AI9=4),OR(BE9=3,BE9=4)),1,0) -> 1 | BS9: =IF(AND(OR(AJ9=3,AJ9=4),OR(BF9=3,BF9=4)),1,0) -> 0 | CC9: 2 | CD9: 2 | CE9: 2 | CF9: 2 | CG9: 2 | CH9: 2 | CI9: 1 | CJ9: 1 | CK9: 2 | CL9: 1 | CM9: 1 | CN9: 2 | CO9: 0 | CP9: 2 | CQ9: 2
A10: 2 | B10: 1 | C10: 1 | D10: 40876 | E10: 1 | F10: 1989 | G10: 1 | H10: 1 | I10: 0 | J10: 1 | K10: 0 | L10: 2 | M10: 3 | N10: 2 | O10: 0 | P10: 1 | Q10: 8 | R10: 1 | S10: 0 | T10: 1 | U10: 1 | V10: 2 | W10: 1 | X10: 5 | Y10: 1 | Z10: 3 | AA10: 2 | AC10: 4 | AD10: 4 | AE10: 4 | AF10: 4 | AG10: 3 | AH10: 3 | AK10: =COUNTIF(AB10:AJ10,1) -> 0 | AL10: =COUNTIF(AB10:AJ10,2) -> 0 | AM10: =COUNTIF(AB10:AJ10,3) -> 2 | AN10: =COUNTIF(AB10:AJ10,4) -> 4 | AO10: 0 | AQ10: 1 | AR10: 1 | AS10: 1 | AT10: 1 | AU10: 1 | AV10: 0 | AY10: 4 | AZ10: 4 | BA10: 4 | BB10: 3 | BC10: 3 | BD10: 3 | BG10: =COUNTIF(AX10:BF10,1) -> 0 | BH10: =COUNTIF(AX10:BF10,2) -> 0 | BI10: =COUNTIF(AX10:BF10,3) -> 3 | BJ10: =COUNTIF(AX10:BF10,4) -> 3 | BK10: =IF(AND(OR(AB10=3,AB10=4),OR(AX10=3,AX10=4)),1,0) -> 0 | BL10: =IF(AND(OR(AC10=3,AC10=4),OR(AY10=3,AY10=4)),1,0) -> 1 | BM10: =IF(AND(OR(AD10=3,AD10=4),OR(AZ10=3,AZ10=4)),1,0) -> 1 | BN10: =IF(AND(OR(AE10=3,AE10=4),OR(BA10=3,BA10=4)),1,0) -> 1 | BO10: =IF(AND(OR(AF10=3,AF10=4),OR(BB10=3,BB10=4)),1,0) -> 1 | BP10: =IF(AND(OR(AG10=3,AG10=4),OR(BC10=3,BC10=4)),1,0) -> 1 | BQ10: =IF(AND(OR(AH10=3,AH10=4),OR(BD10=3,BD10=4)),1,0) -> 1 | BR10: =IF(AND(OR(AI10=3,AI10=4),OR(BE10=3,BE10=4)),1,0) -> 0 | BS10: =IF(AND(OR(AJ10=3,AJ10=4),OR(BF10=3,BF10=4)),1,0) -> 0 | BU10: =SUM(Raw!AR10:AR16) -> 2 | BV10: =SUM(Raw!AS10:AS16) -> 5 | BW10: =SUM(Raw!AT10:AT16) -> 5 | BX10: =SUM(Raw!AU10:AU16) -> 3 | BY10: =SUM(Raw!AV10:AV16) -> 2 | BZ10: =SUM(Raw!AW10:AW16) -> 2 | CC10: 1 | CD10: 2 | CE10: 1 | CF10: 2 | CG10: 1 | CH10: 2 | CI10: 1 | CJ10: 1 | CK10: 2 | CL10: 0 | CM10: 1 | CN10: 2 | CO10: 0 | CP10: 1 | CQ10: 2
